<?xml version="1.0"?>
<sdf version="1.5">
  <model name="parrot_bebop_2">
    <static>false</static>
    <pose>0 0 0.062656 0 0 0</pose>

    <!-- Main Body Link -->
    <link name="body">
      <inertial>
        <mass>0.503</mass>
        <inertia>
          <ixx>1.805e-3</ixx>
          <ixy>-8.619e-7</ixy>
          <iyy>1.764e-3</iyy>
          <ixz>1.555e-5</ixz>
          <iyz>3.595e-7</iyz>
          <izz>3.328e-3</izz>
        </inertia>
      </inertial>

      <!-- Add Collision -->
      <collision name="body_collision">
        <geometry>
          <box>
            <size>0.3 0.3 0.1</size> <!-- Approximate size of the drone body -->
          </box>
        </geometry>
      </collision>

      <visual name="hull">
        <geometry>
          <mesh>
            <uri>model://parrot_bebop_2/meshes/hull.dae</uri>
          </mesh>
        </geometry>
      </visual>
    </link>

    <!-- Front-Left Propeller -->
    <link name="propeller_fl">
      <pose>0.08456 0.11463 -0.00501 0 0 0</pose>
      <inertial>
        <mass>0.01</mass>
        <inertia>
          <ixx>1e-5</ixx>
          <iyy>1e-5</iyy>
          <izz>1e-5</izz>
        </inertia>
      </inertial>

      <!-- Add Collision -->
      <collision name="propeller_fl_collision">
        <geometry>
          <cylinder>
            <radius>0.05</radius>
            <length>0.01</length>
          </cylinder>
        </geometry>
      </collision>

      <visual name="propeller_fl_visual">
        <geometry>
          <mesh>
            <uri>model://parrot_bebop_2/meshes/propeller_fl.dae</uri>
          </mesh>
        </geometry>
      </visual>
    </link>

    <link name="propeller_fr">
      <pose>0.08456 -0.11435 -0.00501 0 0 0</pose>
      <inertial>
        <mass>0.01</mass>
        <inertia>
          <ixx>1e-5</ixx>
          <iyy>1e-5</iyy>
          <izz>1e-5</izz>
        </inertia>
      </inertial>

      <collision name="propeller_fr_collision">
        <geometry>
          <cylinder>
            <radius>0.05</radius>
            <length>0.01</length>
          </cylinder>
        </geometry>
      </collision>

      <visual name="propeller_fr_visual">
        <geometry>
          <mesh>
            <uri>model://parrot_bebop_2/meshes/propeller_fr.dae</uri>
          </mesh>
        </geometry>
      </visual>
    </link>

    <link name="propeller_rl">
      <pose>-0.09035 0.11452 -0.00501 0 0 0</pose>
      <inertial>
        <mass>0.01</mass>
        <inertia>
          <ixx>1e-5</ixx>
          <iyy>1e-5</iyy>
          <izz>1e-5</izz>
        </inertia>
      </inertial>

      <collision name="propeller_rl_collision">
        <geometry>
          <cylinder>
            <radius>0.05</radius>
            <length>0.01</length>
          </cylinder>
        </geometry>
      </collision>

      <visual name="propeller_rl_visual">
        <geometry>
          <mesh>
            <uri>model://parrot_bebop_2/meshes/propeller_rl.dae</uri>
          </mesh>
        </geometry>
      </visual>
    </link>

    <link name="propeller_rr">
      <pose>-0.09035 -0.11423 -0.00501 0 0 0</pose>
      <inertial>
        <mass>0.01</mass>
        <inertia>
          <ixx>1e-5</ixx>
          <iyy>1e-5</iyy>
          <izz>1e-5</izz>
        </inertia>
      </inertial>

      <collision name="propeller_rr_collision">
        <geometry>
          <cylinder>
            <radius>0.05</radius>
            <length>0.01</length>
          </cylinder>
        </geometry>
      </collision>

      <visual name="propeller_rr_visual">
        <geometry>
          <mesh>
            <uri>model://parrot_bebop_2/meshes/propeller_rr.dae</uri>
          </mesh>
        </geometry>
      </visual>
    </link>

    <!-- Joints -->
  

     <joint name="joint_propeller_fl" type="revolute">
      <parent>body</parent>
      <child>propeller_fl</child>
      <axis>
        <xyz>0 0 1</xyz>
        <limit>
          <lower>-3.14</lower>
          <upper>3.14</upper>
          <effort>1e6</effort>
        </limit>
        <dynamics>
          <damping>0.01</damping>
          <friction>0.001</friction>
        </dynamics>
      </axis>
    </joint>

    <joint name="joint_propeller_fr" type="revolute">
      <parent>body</parent>
      <child>propeller_fr</child>
      <axis>
        <xyz>0 0 1</xyz>
        <limit>
          <lower>-3.14</lower>
          <upper>3.14</upper>
          <effort>1e6</effort>
        </limit>
        <dynamics>
          <damping>0.01</damping>
          <friction>0.001</friction>
        </dynamics>
      </axis>
    </joint>

    <joint name="joint_propeller_rl" type="revolute">
      <parent>body</parent>
      <child>propeller_rl</child>
      <axis>
        <xyz>0 0 1</xyz>
        <limit>
          <lower>-3.14</lower>
          <upper>3.14</upper>
          <effort>1e6</effort>
        </limit>
        <dynamics>
          <damping>0.01</damping>
          <friction>0.001</friction>
        </dynamics>
      </axis>
    </joint>

    <joint name="joint_propeller_rr" type="revolute">
      <parent>body</parent>
      <child>propeller_rr</child>
      <axis>
        <xyz>0 0 1</xyz>
        <limit>
          <lower>-3.14</lower>
          <upper>3.14</upper>
          <effort>1e6</effort>
        </limit>
        <dynamics>
          <damping>0.01</damping>
          <friction>0.001</friction>
        </dynamics>
      </axis>
    </joint>

     


  </model>
</sdf>
