<?xml version="1.0"?>
<sdf version="1.6">
  <model name="parrot_bebop_2">
    <pose>0 0 0.062656 0 0 0</pose>

    <frame name="lidar_frame" attached_to='body'>
    <pose>0 0 0.5 0 0 0</pose>
    </frame>

    <!-- Main Body Link -->
    <link name="body">
    <pose frame="">0 0 0 0 -0 0</pose>
      <inertial>
      <pose frame="">0 0 0 0 -0 0</pose>
        <mass>0.503</mass>
        <inertia>
          <ixx>1.805e-3</ixx>
          <ixy>-8.619e-7</ixy>
          <iyy>1.764e-3</iyy>
          <ixz>1.555e-5</ixz>
          <iyz>3.595e-7</iyz>
          <izz>3.328e-3</izz>
        </inertia>
      </inertial>

      <!-- Add Collision -->
      <collision name="body_collision">
      <pose frame="">0 0 0 0 -0 0</pose>
        <geometry>
          <box>
            <size>0.3 0.3 0.1</size> <!-- Approximate size of the drone body -->
          </box>
        </geometry>
      </collision>

      <visual name="hull">
      <pose frame="">0 0 0 0 -0 0</pose>
        <geometry>
          <mesh>
            <uri>model://parrot_bebop_2/meshes/hull.dae</uri>
          </mesh>
        </geometry>
      </visual>

      <!-- LiDAR Sensor-->
      <sensor name = 'gpu_lidar' type = 'gpu_lidar'>
      <pose relative_to='lidar_frame'>0 0 0 0 0 0</pose>
      <topic>lidar</topic>
      <update_rate>0.1</update_rate>
      <ray>
        <scan>
            <horizontal>
                <samples>640</samples>
                <resolution>1</resolution>
                <min_angle>-1.396263</min_angle>
                <max_angle>1.396263</max_angle>
            </horizontal>
            <vertical>
                <samples>1</samples>
                <resolution>0.01</resolution>
                <min_angle>0</min_angle>
                <max_angle>0</max_angle>
            </vertical>
        </scan>
        <range>
            <min>0.08</min>
            <max>10.0</max>
            <resolution>0.01</resolution>
        </range>
    </ray>
    <always_on>1</always_on>
    <visualize>true</visualize>
      
      </sensor>
    </link>

    <!-- Front-Left Propeller -->
    <link name="propeller_fl">
      <pose frame=''>0.08456 0.11463 -0.00501 0 0 0</pose>
      <inertial>
      <pose frame=''>0 0 0 0 -0 0</pose>
        <mass>0.01</mass>
        <inertia>
          <ixx>1e-5</ixx>
          <iyy>1e-5</iyy>
          <izz>1e-5</izz>
        </inertia>
      </inertial>

      <!-- Add Collision -->
      <collision name="propeller_fl_collision">
      <pose frame=''>0 0 0 0 -0 0</pose>
        <geometry>
          <cylinder>
            <radius>0.05</radius>
            <length>0.01</length>
          </cylinder>
        </geometry>
      </collision>

      <visual name="propeller_fl_visual">
      <pose frame=''>0 0 0 0 -0 0</pose>
        <geometry>
          <mesh>
            <uri>model://parrot_bebop_2/meshes/propeller_fl.dae</uri>
          </mesh>
        </geometry>
      </visual>
      <gravity>1</gravity>
      <velocity_decay/>
    </link>

    <!-- FL Joint-->
     <joint name="joint_propeller_fl" type="revolute">
     <child>propeller_fl</child>
      <parent>body</parent>
      <axis>
        <xyz>0 0 1</xyz>
        <limit>
           <lower>-1e+16</lower>
          <upper>1e+16</upper>
        </limit>
        <dynamics>
          <spring_reference>0</spring_reference>
          <spring_stiffness>0</spring_stiffness>
        </dynamics>
        <use_parent_model_frame>1</use_parent_model_frame>
      </axis>
    </joint>

    <!-- Front-Right Propeller -->
    <link name="propeller_fr">
      <pose frame=''>0.08456 -0.11435 -0.00501 0 0 0</pose>
      <inertial>
       <pose frame=''>0 0 0 0 -0 0</pose>
        <mass>0.01</mass>
        <inertia>
          <ixx>1e-5</ixx>
          <iyy>1e-5</iyy>
          <izz>1e-5</izz>
        </inertia>
      </inertial>

      <collision name="propeller_fr_collision">
       <pose frame=''>0 0 0 0 -0 0</pose>
        <geometry>
          <cylinder>
            <radius>0.05</radius>
            <length>0.01</length>
          </cylinder>
        </geometry>
      </collision>

      <visual name="propeller_fr_visual">
       <pose frame=''>0 0 0 0 -0 0</pose>
        <geometry>
          <mesh>
            <uri>model://parrot_bebop_2/meshes/propeller_fr.dae</uri>
          </mesh>
        </geometry>
      </visual>
      <gravity>1</gravity>
      <velocity_decay/>
    </link>

    <!-- FR Joint-->
    <joint name="joint_propeller_fr" type="revolute">
     <child>propeller_fr</child>
      <parent>body</parent>
      <axis>
        <xyz>0 0 1</xyz>
        <limit>
          <lower>-1e+16</lower>
          <upper>1e+16</upper>
        </limit>
        <dynamics>
          <spring_reference>0</spring_reference>
          <spring_stiffness>0</spring_stiffness>
        </dynamics>
        <use_parent_model_frame>1</use_parent_model_frame>
      </axis>
    </joint>

    <!-- Rear-Left Propeller -->
    <link name="propeller_rl">
      <pose frame=''>-0.09035 0.11452 -0.00501 0 0 0</pose>
      <inertial>
      <pose frame=''>0 0 0 0 -0 0</pose>
        <mass>0.01</mass>
        <inertia>
          <ixx>1e-5</ixx>
          <iyy>1e-5</iyy>
          <izz>1e-5</izz>
        </inertia>
      </inertial>

      <collision name="propeller_rl_collision">
      <pose frame=''>0 0 0 0 -0 0</pose>
        <geometry>
          <cylinder>
            <radius>0.05</radius>
            <length>0.01</length>
          </cylinder>
        </geometry>
      </collision>

      <visual name="propeller_rl_visual">
      <pose frame=''>0 0 0 0 -0 0</pose>
        <geometry>
          <mesh>
            <uri>model://parrot_bebop_2/meshes/propeller_rl.dae</uri>
          </mesh>
        </geometry>
      </visual>
      <gravity>1</gravity>
      <velocity_decay/>
    </link>

    <!-- RL Joint-->
    <joint name="joint_propeller_rl" type="revolute">
     <child>propeller_rl</child>
      <parent>body</parent>
      <axis>
        <xyz>0 0 1</xyz>
        <limit>
          <lower>-1e+16</lower>
          <upper>1e+16</upper>
        </limit>
        <dynamics>
          <spring_reference>0</spring_reference>
          <spring_stiffness>0</spring_stiffness>
        </dynamics>
        <use_parent_model_frame>1</use_parent_model_frame>
      </axis>
    </joint>

    <link name="propeller_rr">
      <pose frame=''>-0.09035 -0.11423 -0.00501 0 0 0</pose>
      <inertial>
        <pose frame=''>0 0 0 0 -0 0</pose>
        <mass>0.01</mass>
        <inertia>
          <ixx>1e-5</ixx>
          <iyy>1e-5</iyy>
          <izz>1e-5</izz>
        </inertia>
      </inertial>

      <collision name="propeller_rr_collision">
        <pose frame=''>0 0 0 0 -0 0</pose>
        <geometry>
          <cylinder>
            <radius>0.05</radius>
            <length>0.01</length>
          </cylinder>
        </geometry>
      </collision>

      <visual name="propeller_rr_visual">
        <pose frame=''>0 0 0 0 -0 0</pose>
        <geometry>
          <mesh>
            <uri>model://parrot_bebop_2/meshes/propeller_rr.dae</uri>
          </mesh>
        </geometry>
      </visual>
      <gravity>1</gravity>
      <velocity_decay/>
    </link>

    <!-- RR Joint-->

    <joint name="joint_propeller_rr" type="revolute">
      <child>propeller_rr</child>
      <parent>body</parent>
      <axis>
        <xyz>0 0 1</xyz>
        <limit>
          <lower>-1e+16</lower>
          <upper>1e+16</upper>
        </limit>
        <dynamics>
          <spring_reference>0</spring_reference>
          <spring_stiffness>0</spring_stiffness>
        </dynamics>
        <use_parent_model_frame>1</use_parent_model_frame>
      </axis>
    </joint>
  </model>
</sdf>
